Workbook
Name Slicer_Age: #N/A
Name Slicer_City_tier: #N/A
Name Slicer_Customer_ID: #N/A
Name Slicer_Diabetes_Status: #N/A
Name Slicer_State_ID: #N/A
Name Slicer_Weight_Status: #N/A

Sheet Customer Names
A1: Customer ID | B1: name | C1: Last name | D1: Title | E1: First name
A2: Id1 | B2: Hawks, Ms. Kelly | C2: =LEFT(B2,FIND(",",B2)-1) -> Hawks | D2: Ms | E2: Kelly
A3: Id2 | B3: Lehner, Mr. Matthew D | C3: =LEFT(B3,FIND(",",B3)-1) -> Lehner | D3: Mr | E3: Matthew D
A4: Id3 | B4: Lu, Mr. Phil | C4: =LEFT(B4,FIND(",",B4)-1) -> Lu | D4: Mr | E4: Phil
A5: Id4 | B5: Osborne, Ms. Kelsey | C5: =LEFT(B5,FIND(",",B5)-1) -> Osborne | D5: Ms | E5: Kelsey
A6: Id5 | B6: Kadala, Ms. Kristyn | C6: =LEFT(B6,FIND(",",B6)-1) -> Kadala | D6: Ms | E6: Kristyn
A7: Id6 | B7: Baker, Mr. Russell B. | C7: =LEFT(B7,FIND(",",B7)-1) -> Baker | D7: Mr | E7: Russell B
A8: Id7 | B8: Macpherson, Mr. Scott | C8: =LEFT(B8,FIND(",",B8)-1) -> Macpherson | D8: Mr | E8: Scott
A9: Id8 | B9: Hallman, Mr. Stephen | C9: =LEFT(B9,FIND(",",B9)-1) -> Hallman | D9: Mr | E9: Stephen
A10: Id9 | B10: Moran, Mr. Patrick R. | C10: =LEFT(B10,FIND(",",B10)-1) -> Moran | D10: Mr | E10: Patrick R
A11: Id10 | B11: Benner, Ms. Brooke N. | C11: =LEFT(B11,FIND(",",B11)-1) -> Benner | D11: Ms | E11: Brooke N
A12: Id11 | B12: Fierro Vargas, Ms. Paola Andrea | C12: =LEFT(B12,FIND(",",B12)-1) -> Fierro Vargas | D12: Ms | E12: Paola Andrea
A13: Id12 | B13: Franz, Mr. David | C13: =LEFT(B13,FIND(",",B13)-1) -> Franz | D13: Mr | E13: David
... A2334: Id2333 | B2334: Albano, Ms. Julie | C2334: =LEFT(B2334,FIND(",",B2334)-1) -> Albano | D2334: Ms | E2334: Julie
A2335: Id2334 | B2335: Rosendahl, Mr. Evan P | C2335: =LEFT(B2335,FIND(",",B2335)-1) -> Rosendahl | E2335: Evan P
A2336: Id2335 | B2336: German, Mr. Aaron K | C2336: =LEFT(B2336,FIND(",",B2336)-1) -> German | E2336: Aaron K

Sheet Medical Examinations
A1: Customer ID | B1: BMI | C1: Weight Status | D1: HBA1C | E1: Diabetes Status | F1: Heart Issues | G1: Any Transplants | H1: Cancer history | I1: NumberOfMajorSurgeries | J1: smoker
A2: Id1 | B2: 47.41 | C2: =IF(B2<18.5,"Underweight", IF(B2<=24.9,"Normal Weight", IF(B2<=29.9,"Overweight","Obesity"))) -> Obesity | D2: 7.47 | E2: =IF(D2<5.7,"Normal",IF(D2<=6.4,"Prediabetes","Diabetes")) -> Diabetes | F2: No | G2: No | H2: No | I2: 0 | J2: Yes | L2: =COUNTIF(A:A," ") -> 0 | M2: {=_xlfn.UNIQUE(F:F)} -> Heart Issues | O2: {=_xlfn.UNIQUE(J:J)} -> smoker
A3: Id2 | B3: 30.36 | C3: =IF(B3<18.5,"Underweight", IF(B3<=24.9,"Normal Weight", IF(B3<=29.9,"Overweight","Obesity"))) -> Obesity | D3: 5.77 | E3: =IF(D3<5.7,"Normal",IF(D3<=6.4,"Prediabetes","Diabetes")) -> Prediabetes | F3: No | G3: No | H3: No | I3: 0 | J3: Yes | L3: =COUNTIF(B:B,"?") -> 0 | M3: No | O3: Yes
A4: Id3 | B4: 34.485 | C4: =IF(B4<18.5,"Underweight", IF(B4<=24.9,"Normal Weight", IF(B4<=29.9,"Overweight","Obesity"))) -> Obesity | D4: 11.87 | E4: =IF(D4<5.7,"Normal",IF(D4<=6.4,"Prediabetes","Diabetes")) -> Diabetes | F4: Yes | G4: No | H4: No | I4: 2 | J4: Yes | L4: =COUNTIF(D:D,"?") -> 0 | M4: Yes | O4: No
A5: Id4 | B5: 38.095 | C5: =IF(B5<18.5,"Underweight", IF(B5<=24.9,"Normal Weight", IF(B5<=29.9,"Overweight","Obesity"))) -> Obesity | D5: 6.05 | E5: =IF(D5<5.7,"Normal",IF(D5<=6.4,"Prediabetes","Diabetes")) -> Prediabetes | F5: No | G5: No | H5: No | I5: 0 | J5: Yes | L5: =COUNTIF(F:F,"?") -> 0 | M5: 0 | O5: 0
A6: Id5 | B6: 35.53 | C6: =IF(B6<18.5,"Underweight", IF(B6<=24.9,"Normal Weight", IF(B6<=29.9,"Overweight","Obesity"))) -> Obesity | D6: 5.45 | E6: =IF(D6<5.7,"Normal",IF(D6<=6.4,"Prediabetes","Diabetes")) -> Normal | F6: No | G6: No | H6: No | I6: 0 | J6: Yes | L6: =COUNTIF(G:G,"?") -> 0 | M6: =COUNTIF(F:F,"0") -> 0
A7: Id6 | B7: 32.8 | C7: =IF(B7<18.5,"Underweight", IF(B7<=24.9,"Normal Weight", IF(B7<=29.9,"Overweight","Obesity"))) -> Obesity | D7: 6.59 | E7: =IF(D7<5.7,"Normal",IF(D7<=6.4,"Prediabetes","Diabetes")) -> Diabetes | F7: No | G7: No | H7: No | I7: 0 | J7: Yes | L7: =COUNTIF(H:H,"?") -> 0
A8: Id7 | B8: 36.4 | C8: =IF(B8<18.5,"Underweight", IF(B8<=24.9,"Normal Weight", IF(B8<=29.9,"Overweight","Obesity"))) -> Obesity | D8: 6.07 | E8: =IF(D8<5.7,"Normal",IF(D8<=6.4,"Prediabetes","Diabetes")) -> Prediabetes | F8: No | G8: No | H8: No | I8: 0 | J8: Yes | L8: =COUNTIF(I:I,"?") -> 0
A9: Id8 | B9: 36.96 | C9: =IF(B9<18.5,"Underweight", IF(B9<=24.9,"Normal Weight", IF(B9<=29.9,"Overweight","Obesity"))) -> Obesity | D9: 7.93 | E9: =IF(D9<5.7,"Normal",IF(D9<=6.4,"Prediabetes","Diabetes")) -> Diabetes | F9: No | G9: No | H9: No | I9: 3 | J9: Yes | L9: =COUNTIF(J:J,"?") -> 0
A10: Id9 | B10: 41.14 | C10: =IF(B10<18.5,"Underweight", IF(B10<=24.9,"Normal Weight", IF(B10<=29.9,"Overweight","Obesity"))) -> Obesity | D10: 9.58 | E10: =IF(D10<5.7,"Normal",IF(D10<=6.4,"Prediabetes","Diabetes")) -> Diabetes | F10: Yes | G10: No | H10: Yes | I10: 1 | J10: Yes
A11: Id10 | B11: 38.06 | C11: =IF(B11<18.5,"Underweight", IF(B11<=24.9,"Normal Weight", IF(B11<=29.9,"Overweight","Obesity"))) -> Obesity | D11: 10.79 | E11: =IF(D11<5.7,"Normal",IF(D11<=6.4,"Prediabetes","Diabetes")) -> Diabetes | F11: No | G11: No | H11: No | I11: 0 | J11: Yes | L11: =COUNTIF(J:J,"yes") -> 488
A12: Id11 | B12: 37.7 | C12: =IF(B12<18.5,"Underweight", IF(B12<=24.9,"Normal Weight", IF(B12<=29.9,"Overweight","Obesity"))) -> Obesity | D12: 5.96 | E12: =IF(D12<5.7,"Normal",IF(D12<=6.4,"Prediabetes","Diabetes")) -> Prediabetes | F12: Yes | G12: No | H12: No | I12: 2 | J12: Yes | L12: =COUNTIF(J:J,"No") -> 1847
A13: Id12 | B13: 42.13 | C13: =IF(B13<18.5,"Underweight", IF(B13<=24.9,"Normal Weight", IF(B13<=29.9,"Overweight","Obesity"))) -> Obesity | D13: 11.9 | E13: =IF(D13<5.7,"Normal",IF(D13<=6.4,"Prediabetes","Diabetes")) -> Diabetes | F13: No | G13: No | H13: No | I13: 0 | J13: Yes
A14: Id13 | B14: 40.92 | C14: =IF(B14<18.5,"Underweight", IF(B14<=24.9,"Normal Weight", IF(B14<=29.9,"Overweight","Obesity"))) -> Obesity | D14: 8.41 | E14: =IF(D14<5.7,"Normal",IF(D14<=6.4,"Prediabetes","Diabetes")) -> Diabetes | F14: No | G14: No | H14: No | I14: 0 | J14: Yes
A15: Id14 | B15: 40.565 | C15: =IF(B15<18.5,"Underweight", IF(B15<=24.9,"Normal Weight", IF(B15<=29.9,"Overweight","Obesity"))) -> Obesity | D15: 7.02 | E15: =IF(D15<5.7,"Normal",IF(D15<=6.4,"Prediabetes","Diabetes")) -> Diabetes | F15: No | G15: No | H15: No | I15: 0 | J15: Yes
A16: Id15 | B16: 36.385 | C16: =IF(B16<18.5,"Underweight", IF(B16<=24.9,"Normal Weight", IF(B16<=29.9,"Overweight","Obesity"))) -> Obesity | D16: 7.59 | E16: =IF(D16<5.7,"Normal",IF(D16<=6.4,"Prediabetes","Diabetes")) -> Diabetes | F16: Yes | G16: No | H16: No | I16: 2 | J16: Yes
A17: Id16 | B17: 39.9 | C17: =IF(B17<18.5,"Underweight", IF(B17<=24.9,"Normal Weight", IF(B17<=29.9,"Overweight","Obesity"))) -> Obesity | D17: 11.32 | E17: =IF(D17<5.7,"Normal",IF(D17<=6.4,"Prediabetes","Diabetes")) -> Diabetes | F17: No | G17: No | H17: No | I17: 0 | J17: Yes
A18: Id17 | B18: 33.8 | C18: =IF(B18<18.5,"Underweight", IF(B18<=24.9,"Normal Weight", IF(B18<=29.9,"Overweight","Obesity"))) -> Obesity | D18: 7.67 | E18: =IF(D18<5.7,"Normal",IF(D18<=6.4,"Prediabetes","Diabetes")) -> Diabetes | F18: No | G18: No | H18: No | I18: 3 | J18: Yes
A19: Id18 | B19: 36.765 | C19: =IF(B19<18.5,"Underweight", IF(B19<=24.9,"Normal Weight", IF(B19<=29.9,"Overweight","Obesity"))) -> Obesity | D19: 7.29 | E19: =IF(D19<5.7,"Normal",IF(D19<=6.4,"Prediabetes","Diabetes")) -> Diabetes | F19: Yes | G19: No | H19: Yes | I19: 1 | J19: Yes
A20: Id19 | B20: 36.955 | C20: =IF(B20<18.5,"Underweight", IF(B20<=24.9,"Normal Weight", IF(B20<=29.9,"Overweight","Obesity"))) -> Obesity | D20: 4.72 | E20: =IF(D20<5.7,"Normal",IF(D20<=6.4,"Prediabetes","Diabetes")) -> Normal | F20: Yes | G20: No | H20: No | I20: 1 | J20: Yes
A21: Id20 | B21: 42.9 | C21: =IF(B21<18.5,"Underweight", IF(B21<=24.9,"Normal Weight", IF(B21<=29.9,"Overweight","Obesity"))) -> Obesity | D21: 11.41 | E21: =IF(D21<5.7,"Normal",IF(D21<=6.4,"Prediabetes","Diabetes")) -> Diabetes | F21: No | G21: No | H21: No | I21: 0 | J21: Yes
A22: Id21 | B22: 36.3 | C22: =IF(B22<18.5,"Underweight", IF(B22<=24.9,"Normal Weight", IF(B22<=29.9,"Overweight","Obesity"))) -> Obesity | D22: 11.5 | E22: =IF(D22<5.7,"Normal",IF(D22<=6.4,"Prediabetes","Diabetes")) -> Diabetes | F22: Yes | G22: No | H22: No | I22: 2 | J22: Yes
A23: Id22 | B23: 32.2 | C23: =IF(B23<18.5,"Underweight", IF(B23<=24.9,"Normal Weight", IF(B23<=29.9,"Overweight","Obesity"))) -> Obesity | D23: 6.22 | E23: =IF(D23<5.7,"Normal",IF(D23<=6.4,"Prediabetes","Diabetes")) -> Prediabetes | F23: Yes | G23: No | H23: No | I23: 2 | J23: Yes
A24: Id23 | B24: 31.3 | C24: =IF(B24<18.5,"Underweight", IF(B24<=24.9,"Normal Weight", IF(B24<=29.9,"Overweight","Obesity"))) -> Obesity | D24: 11.38 | E24: =IF(D24<5.7,"Normal",IF(D24<=6.4,"Prediabetes","Diabetes")) -> Diabetes | F24: No | G24: No | H24: No | I24: 3 | J24: Yes
... A2336: Id2335 | B2336: 17.58 | C2336: =IF(B2336<18.5,"Underweight", IF(B2336<=24.9,"Normal Weight", IF(B2336<=29.9,"Overweight","Obesity"))) -> Underweight | D2336: 4.51 | E2336: =IF(D2336<5.7,"Normal",IF(D2336<=6.4,"Prediabetes","Diabetes")) -> Normal | F2336: No | G2336: No | H2336: No | I2336: 1 | J2336: No

Sheet Hospitalisation Details
A1: Customer ID | B1: Year | C1: month | D1: date | E1: Date of Birth | F1: Age | G1: children | H1: charges | I1: Hospital tier | J1: City tier | K1: State ID
A2: Id2335 | B2: 1992 | C2: Jul | D2: 9 | E2: =DATE(B2,MONTH(1&C2),D2) -> 33794 | F2: =DATEDIF(E2, "2023-6-8", "Y") & "Years" -> 30Years | G2: 0 | H2: 563.84 | I2: tier - 2 | J2: tier - 3 | K2: R1013
A3: Id2334 | B3: 1992 | C3: Nov | D3: 30 | E3: =DATE(B3,MONTH(1&C3),D3) -> 33938 | F3: =DATEDIF(E3, "2023-6-8", "Y") & "Years" -> 30Years | G3: 0 | H3: 570.62 | I3: tier - 2 | J3: tier - 1 | K3: R1013 | M3: =COUNTIF(A:A, "?") -> 6
A4: Id2333 | B4: 1993 | C4: Jun | D4: 30 | E4: =DATE(B4,MONTH(1&C4),D4) -> 34150 | F4: =DATEDIF(E4, "2023-6-8", "Y") & "Years" -> 29Years | G4: 0 | H4: 600 | I4: tier - 2 | J4: tier - 1 | K4: R1013 | M4: =COUNTIF(B:B,"?") -> 0
A5: Id2332 | B5: 1992 | C5: Sep | D5: 13 | E5: =DATE(B5,MONTH(1&C5),D5) -> 33860 | F5: =DATEDIF(E5, "2023-6-8", "Y") & "Years" -> 30Years | G5: 0 | H5: 604.54 | I5: tier - 3 | J5: tier - 3 | K5: R1013 | M5: =COUNTIF(C:C,"?") -> 0
A6: Id2331 | B6: 1998 | C6: Jul | D6: 27 | E6: =DATE(B6,MONTH(1&C6),D6) -> 36003 | F6: =DATEDIF(E6, "2023-6-8", "Y") & "Years" -> 24Years | G6: 0 | H6: 637.26 | I6: tier - 3 | J6: tier - 3 | K6: R1013 | M6: =COUNTIF(D:D, " ") -> 0
A7: Id2330 | B7: 2001 | C7: Nov | D7: 20 | E7: =DATE(B7,MONTH(1&C7),D7) -> 37215 | F7: =DATEDIF(E7, "2023-6-8", "Y") & "Years" -> 21Years | G7: 0 | H7: 646.14 | I7: tier - 3 | J7: tier - 3 | K7: R1012 | M7: =COUNTIF(I:I,"?") -> 0
A8: Id2329 | B8: 1993 | C8: Jun | D8: 1 | E8: =DATE(B8,MONTH(1&C8),D8) -> 34121 | F8: =DATEDIF(E8, "2023-6-8", "Y") & "Years" -> 30Years | G8: 0 | H8: 650 | I8: tier - 3 | J8: tier - 3 | K8: R1013 | M8: =COUNTIF(J:J,"?") -> 0
A9: Id2328 | B9: 1995 | C9: Jul | D9: 4 | E9: =DATE(B9,MONTH(1&C9),D9) -> 34884 | F9: =DATEDIF(E9, "2023-6-8", "Y") & "Years" -> 27Years | G9: 0 | H9: 650 | I9: tier - 3 | J9: tier - 3 | K9: R1013 | M9: =COUNTIF(K:K,"?") -> 0
A10: Id2327 | B10: 2002 | C10: Nov | D10: 29 | E10: =DATE(B10,MONTH(1&C10),D10) -> 37589 | F10: =DATEDIF(E10, "2023-6-8", "Y") & "Years" -> 20Years | G10: 0 | H10: 668 | I10: tier - 3 | J10: tier - 2 | K10: R1012 | M10: =AVERAGE(B:B) -> 1982.8417
A11: Id2326 | B11: 1997 | C11: Nov | D11: 9 | E11: =DATE(B11,MONTH(1&C11),D11) -> 35743 | F11: =DATEDIF(E11, "2023-6-8", "Y") & "Years" -> 25Years | G11: 0 | H11: 670 | I11: tier - 3 | J11: tier - 3 | K11: R1013 | M11: =ROUND(AVERAGE(B:B),0) -> 1983
A12: Id2325 | B12: 2001 | C12: Sep | D12: 12 | E12: =DATE(B12,MONTH(1&C12),D12) -> 37146 | F12: =DATEDIF(E12, "2023-6-8", "Y") & "Years" -> 21Years | G12: 0 | H12: 687.54 | I12: tier - 3 | J12: tier - 2 | K12: R1013
A13: Id2324 | B13: 1999 | C13: Dec | D13: 26 | E13: =DATE(B13,MONTH(1&C13),D13) -> 36520 | F13: =DATEDIF(E13, "2023-6-8", "Y") & "Years" -> 23Years | G13: 0 | H13: 700 | I13: tier - 2 | J13: tier - 3 | K13: R1013 | M13: =COUNTIF(I:I, "tier - 1") -> 309
A14: Id2323 | B14: 1999 | C14: Dec | D14: 14 | E14: =DATE(B14,MONTH(1&C14),D14) -> 36508 | F14: =DATEDIF(E14, "2023-6-8", "Y") & "Years" -> 23Years | G14: 0 | H14: 722.99 | I14: tier - 3 | J14: tier - 1 | K14: R1013 | M14: =COUNTIF(I:I,"tier - 2") -> 1340
A15: Id2322 | B15: 2002 | C15: Sep | D15: 19 | E15: =DATE(B15,MONTH(1&C15),D15) -> 37518 | F15: =DATEDIF(E15, "2023-6-8", "Y") & "Years" -> 20Years | G15: 0 | H15: 750 | I15: tier - 3 | J15: tier - 1 | K15: R1012 | M15: =COUNTIF(I:I,"tier - 3") -> 694
A16: Id2321 | B16: 1993 | C16: Aug | D16: 9 | E16: =DATE(B16,MONTH(1&C16),D16) -> 34190 | F16: =DATEDIF(E16, "2023-6-8", "Y") & "Years" -> 29Years | G16: 0 | H16: 760 | I16: tier - 3 | J16: tier - 1 | K16: R1013
A17: Id2320 | B17: 1996 | C17: Oct | D17: 22 | E17: =DATE(B17,MONTH(1&C17),D17) -> 35360 | F17: =DATEDIF(E17, "2023-6-8", "Y") & "Years" -> 26Years | G17: 0 | H17: 760 | I17: tier - 3 | J17: tier - 3 | K17: R1013 | M17: =COUNTIF(J:J,"tier - 1") -> 734
A18: Id2319 | B18: 1993 | C18: Jun | D18: 28 | E18: =DATE(B18,MONTH(1&C18),D18) -> 34148 | F18: =DATEDIF(E18, "2023-6-8", "Y") & "Years" -> 29Years | G18: 0 | H18: 770 | I18: tier - 3 | J18: tier - 3 | K18: R1013 | M18: =COUNTIF(J:J,"tier - 2") -> 813
A19: Id2318 | B19: 1996 | C19: Sep | D19: 18 | E19: =DATE(B19,MONTH(1&C19),D19) -> 35326 | F19: =DATEDIF(E19, "2023-6-8", "Y") & "Years" -> 26Years | G19: 0 | H19: 770.38 | I19: tier - 3 | J19: tier - 2 | K19: R1012 | M19: =COUNTIF(J:J,"tier - 3") -> 796
A20: Id2317 | B20: 1995 | C20: Dec | D20: 7 | E20: =DATE(B20,MONTH(1&C20),D20) -> 35040 | F20: =DATEDIF(E20, "2023-6-8", "Y") & "Years" -> 27Years | G20: 0 | H20: 773.54 | I20: tier - 3 | J20: tier - 2 | K20: R1013
A21: Id2316 | B21: 2004 | C21: Oct | D21: 7 | E21: =DATE(B21,MONTH(1&C21),D21) -> 38267 | F21: =DATEDIF(E21, "2023-6-8", "Y") & "Years" -> 18Years | G21: 0 | H21: 830.52 | I21: tier - 3 | J21: tier - 2 | K21: R1011
A22: Id2315 | B22: 2000 | C22: Nov | D22: 18 | E22: =DATE(B22,MONTH(1&C22),D22) -> 36848 | F22: =DATEDIF(E22, "2023-6-8", "Y") & "Years" -> 22Years | G22: 0 | H22: 865.41 | I22: tier - 3 | J22: tier - 1 | K22: R1013
A23: Id2314 | B23: 1993 | C23: Nov | D23: 27 | E23: =DATE(B23,MONTH(1&C23),D23) -> 34300 | F23: =DATEDIF(E23, "2023-6-8", "Y") & "Years" -> 29Years | G23: 0 | H23: 896.21 | I23: tier - 3 | J23: tier - 1 | K23: R1013
A24: Id2313 | B24: 1994 | C24: Oct | D24: 30 | E24: =DATE(B24,MONTH(1&C24),D24) -> 34637 | F24: =DATEDIF(E24, "2023-6-8", "Y") & "Years" -> 28Years | G24: 0 | H24: 915.07 | I24: tier - 3 | J24: tier - 1 | K24: R1013
A25: Id2312 | B25: 1995 | C25: Oct | D25: 28 | E25: =DATE(B25,MONTH(1&C25),D25) -> 35000 | F25: =DATEDIF(E25, "2023-6-8", "Y") & "Years" -> 27Years | G25: 0 | H25: 928.59 | I25: tier - 3 | J25: tier - 1 | K25: R1013
A26: Id2311 | B26: 2001 | C26: Aug | D26: 19 | E26: =DATE(B26,MONTH(1&C26),D26) -> 37122 | F26: =DATEDIF(E26, "2023-6-8", "Y") & "Years" -> 21Years | G26: 0 | H26: 964.71 | I26: tier - 3 | J26: tier - 2 | K26: R1013
A27: Id2310 | B27: 1994 | C27: Nov | D27: 22 | E27: =DATE(B27,MONTH(1&C27),D27) -> 34660 | F27: =DATEDIF(E27, "2023-6-8", "Y") & "Years" -> 28Years | G27: 0 | H27: 1006.65 | I27: tier - 3 | J27: tier - 2 | K27: R1013
A28: Id2309 | B28: 2000 | C28: Oct | D28: 9 | E28: =DATE(B28,MONTH(1&C28),D28) -> 36808 | F28: =DATEDIF(E28, "2023-6-8", "Y") & "Years" -> 22Years | G28: 0 | H28: 1012 | I28: tier - 3 | J28: tier - 2 | K28: R1013
A29: Id2308 | B29: 1999 | C29: Aug | D29: 5 | E29: =DATE(B29,MONTH(1&C29),D29) -> 36377 | F29: =DATEDIF(E29, "2023-6-8", "Y") & "Years" -> 23Years | G29: 0 | H29: 1019 | I29: tier - 3 | J29: tier - 2 | K29: R1013
A30: Id2307 | B30: 1995 | C30: Oct | D30: 5 | E30: =DATE(B30,MONTH(1&C30),D30) -> 34977 | F30: =DATEDIF(E30, "2023-6-8", "Y") & "Years" -> 27Years | G30: 0 | H30: 1033.74 | I30: tier - 3 | J30: tier - 1 | K30: R1013
A31: Id2306 | B31: 1994 | C31: Nov | D31: 17 | E31: =DATE(B31,MONTH(1&C31),D31) -> 34655 | F31: =DATEDIF(E31, "2023-6-8", "Y") & "Years" -> 28Years | G31: 0 | H31: 1044 | I31: tier - 3 | J31: tier - 2 | K31: R1013
... A153: Id2185 | B153: 2004 | C153: Sep | D153: 11 | E153: =DATE(B153,MONTH(1&C153),D153) -> 38241 | F153: =DATEDIF(E153, "2023-6-8", "Y") & "Years" -> 18Years | G153: 1 | H153: 1720.35 | I153: tier - 3 | J153: tier - 3 | K153: R1013
A154: Id2184 | B154: 2004 | C154: Oct | D154: 21 | E154: =DATE(B154,MONTH(1&C154),D154) -> 38281 | F154: =DATEDIF(E154, "2023-6-8", "Y") & "Years" -> 18Years | G154: 1 | H154: 1725.55 | I154: tier - 3 | J154: tier - 2 | K154: R1013 | M154: =DATEDIF(B2,DATE(2023,6,8),"Y") -> 117
A155: Id2183 | B155: 2004 | C155: Sep | D155: 9 | E155: =DATE(B155,MONTH(1&C155),D155) -> 38239 | F155: =DATEDIF(E155, "2023-6-8", "Y") & "Years" -> 18Years | G155: 1 | H155: 1727.54 | I155: tier - 3 | J155: tier - 1 | K155: R1013
A156: Id2182 | B156: 2003 | C156: Nov | D156: 21 | E156: =DATE(B156,MONTH(1&C156),D156) -> 37946 | F156: =DATEDIF(E156, "2023-6-8", "Y") & "Years" -> 19Years | G156: 0 | H156: 1727.79 | I156: tier - 3 | J156: tier - 3 | K156: R1011
A157: Id2181 | B157: 2003 | C157: Sep | D157: 1 | E157: =DATE(B157,MONTH(1&C157),D157) -> 37865 | F157: =DATEDIF(E157, "2023-6-8", "Y") & "Years" -> 19Years | G157: 0 | H157: 1728.9 | I157: tier - 3 | J157: tier - 2 | K157: R1011
A158: Id2180 | B158: 2003 | C158: Nov | D158: 9 | E158: =DATE(B158,MONTH(1&C158),D158) -> 37934 | F158: =DATEDIF(E158, "2023-6-8", "Y") & "Years" -> 19Years | G158: 0 | H158: 1731.68 | I158: tier - 3 | J158: tier - 2 | K158: R1011
A159: Id2179 | B159: 2003 | C159: Nov | D159: 14 | E159: =DATE(B159,MONTH(1&C159),D159) -> 37939 | F159: =DATEDIF(E159, "2023-6-8", "Y") & "Years" -> 19Years | G159: 0 | H159: 1737.38 | I159: tier - 3 | J159: tier - 2 | K159: R1011
A160: Id2178 | B160: 2003 | C160: Jul | D160: 25 | E160: =DATE(B160,MONTH(1&C160),D160) -> 37827 | F160: =DATEDIF(E160, "2023-6-8", "Y") & "Years" -> 19Years | G160: 0 | H160: 1743.21 | I160: tier - 3 | J160: tier - 1 | K160: R1011
A161: Id2177 | B161: 2003 | C161: Jul | D161: 28 | E161: =DATE(B161,MONTH(1&C161),D161) -> 37830 | F161: =DATEDIF(E161, "2023-6-8", "Y") & "Years" -> 19Years | G161: 0 | H161: 1744.47 | I161: tier - 3 | J161: tier - 1 | K161: R1011
...

Sheet  PivotTable &Charts
A3: Cancer history | B3: Non smoker
A4: Cancer history | B4: Non smoker | C4: Smoker
A5: No | B5: 295 | C5: 68
A6: Yes | B6: 51 | C6: 17
A11: Transplants | B11: Sum of HBA1C | C11: Sum of NumberOfMajorSurgeries
A12: No | B12: 2673.38 | C12: 236
A13: yes | B13: 123.28 | C13: 26
A14: Grand Total | B14: 2796.66 | C14: 262
A22: Sum of charges | B22: Column Labels
A23: Weight Status | B23: Diabetes | C23: Normal | D23: Prediabetes
A24: Normal Weight | B24: 1726354.5 | C24: 1674180.5 | D24: 841586.97
A41: Average of charges | B41: Column Labels
A42: State ID | B42: tier - 1 | C42: tier - 2 | D42: tier - 3
A43: R1011 | B43: 26774.072 | C43: 14881.851 | D43: 6911.7608
A44: R1012 | B44: 20969.12 | C44: 9234.7313 | D44: 9657.3261
A45: R1013 | B45: 16950.201 | C45: 6177.7274 | D45: 6713.9953
A46: R1014 | C46: 2395.17 | D46: 22412.65
A47: R1015 | C47: 11028.98
A48: R1016 | C48: 10145.207 | D48: 8360.4275
A49: R1017 | B49: 26486.95 | C49: 9391.2017 | D49: 9102.986
A50: R1018 | C50: 1704.7 | D50: 13747.87
A51: R1019 | C51: 5309.274 | D51: 21259.38
A52: R1023 | C52: 14451.84
A53: R1024 | B53: 19785.87 | C53: 10335.935 | D53: 15050.606
A54: Unknown | B54: 4827.9
A66: Age | B66: Sum of HBA1C | C66: Sum of BMI
A67: 18Years | B67: 81.2 | C67: 351.44
A68: 19Years | B68: 92.78 | C68: 368.405
A69: 20Years | B69: 131.33 | C69: 324.9
A70: 21Years | B70: 55.8 | C70: 242.27
A71: 22Years | B71: 36.78 | C71: 153.745
A72: 23Years | B72: 55.86 | C72: 246.025
A73: 24Years | B73: 62.88 | C73: 271.97
A74: 25Years | B74: 53.4 | C74: 227.14
A75: 26Years | B75: 40.23 | C75: 169.22
A76: 27Years | B76: 61.89 | C76: 282.17
A77: 28Years | B77: 71.81 | C77: 314.38
A78: 29Years | B78: 35.74 | C78: 152.78
... A113: 64Years | B113: 31.67 | C113: 71.45
A117: Age | B117: Sum of charges
...

Sheet Dash Board

Sheet Health care
A1: Customer ID | B1: BMI | C1: Weight Status | D1: HBA1C | E1: Diabetes Status | F1: Heart Issues | G1: Any Transplants | H1: Cancer history | I1: NumberOfMajorSurgeries | J1: smoker | K1: Date of Birth | L1: Age | M1: charges | N1: Hospital tier | O1: City tier | P1: State ID | Q1: First name
A2: Id1 | B2: {=VLOOKUP(A2,'Medical Examinations'!A1:J2336,{2,3,4,5,6,7,8,9},FALSE)} -> 47.41 | C2: Obesity | D2: 7.47 | E2: Diabetes | F2: No | G2: No | H2: No | I2: 0 | J2: Yes | K2: {=VLOOKUP(A2,'Hospitalisation Details'!$A$1:K2344,{5,6,8,9,10,11},FALSE)} -> 25123 | L2: 54Years | M2: 63770.43 | N2: tier - 1 | O2: tier - 3 | P2: R1013 | Q2: =VLOOKUP(A2,'Customer Names'!$A$1:E2336,5,FALSE) -> Kelly
A3: Id2 | B3: {=VLOOKUP(A3,'Medical Examinations'!A2:J2337,{2,3,4,5,6,7,8,9},FALSE)} -> 30.36 | C3: Obesity | D3: 5.77 | E3: Prediabetes | F3: No | G3: No | H3: No | I3: 0 | J3: Yes | K3: {=VLOOKUP(A3,'Hospitalisation Details'!$A$1:K2345,{5,6,8,9,10,11},FALSE)} -> 28284 | L3: 46Years | M3: 62592.87 | N3: tier - 2 | O3: tier - 3 | P3: R1013 | Q3: =VLOOKUP(A3,'Customer Names'!$A$1:E2337,5,FALSE) -> Matthew D
A4: Id3 | B4: {=VLOOKUP(A4,'Medical Examinations'!A3:J2338,{2,3,4,5,6,7,8,9},FALSE)} -> 34.485 | C4: Obesity | D4: 11.87 | E4: Diabetes | F4: Yes | G4: No | H4: No | I4: 2 | J4: Yes | K4: {=VLOOKUP(A4,'Hospitalisation Details'!$A$1:K2346,{5,6,8,9,10,11},FALSE)} -> 25822 | L4: 52Years | M4: 60021.4 | N4: tier - 1 | O4: tier - 1 | P4: R1012 | Q4: =VLOOKUP(A4,'Customer Names'!$A$1:E2338,5,FALSE) -> Phil
A5: Id4 | B5: {=VLOOKUP(A5,'Medical Examinations'!A4:J2339,{2,3,4,5,6,7,8,9},FALSE)} -> 38.095 | C5: Obesity | D5: 6.05 | E5: Prediabetes | F5: No | G5: No | H5: No | I5: 0 | J5: Yes | K5: {=VLOOKUP(A5,'Hospitalisation Details'!$A$1:K2347,{5,6,8,9,10,11},FALSE)} -> 33395 | L5: 32Years | M5: 58571.07 | N5: tier - 1 | O5: tier - 3 | P5: R1024 | Q5: =VLOOKUP(A5,'Customer Names'!$A$1:E2339,5,FALSE) -> Kelsey
A6: Id5 | B6: {=VLOOKUP(A6,'Medical Examinations'!A5:J2340,{2,3,4,5,6,7,8,9},FALSE)} -> 35.53 | C6: Obesity | D6: 5.45 | E6: Normal | F6: No | G6: No | H6: No | I6: 0 | J6: Yes | K6: {=VLOOKUP(A6,'Hospitalisation Details'!$A$1:K2348,{5,6,8,9,10,11},FALSE)} -> 32678 | L6: 33Years | M6: 55135.4 | N6: tier - 1 | O6: tier - 2 | P6: R1012 | Q6: =VLOOKUP(A6,'Customer Names'!$A$1:E2340,5,FALSE) -> Kristyn
A7: Id6 | B7: {=VLOOKUP(A7,'Medical Examinations'!A6:J2341,{2,3,4,5,6,7,8,9},FALSE)} -> 32.8 | C7: Obesity | D7: 6.59 | E7: Diabetes | F7: No | G7: No | H7: No | I7: 0 | J7: Yes | K7: {=VLOOKUP(A7,'Hospitalisation Details'!$A$1:K2349,{5,6,8,9,10,11},FALSE)} -> 22862 | L7: 60Years | M7: 52590.83 | N7: tier - 1 | O7: tier - 3 | P7: R1011 | Q7: =VLOOKUP(A7,'Customer Names'!$A$1:E2341,5,FALSE) -> Russell B
A8: Id7 | B8: {=VLOOKUP(A8,'Medical Examinations'!A7:J2342,{2,3,4,5,6,7,8,9},FALSE)} -> 36.4 | C8: Obesity | D8: 6.07 | E8: Prediabetes | F8: No | G8: No | H8: No | I8: 0 | J8: Yes | K8: {=VLOOKUP(A8,'Hospitalisation Details'!$A$1:K2350,{5,6,8,9,10,11},FALSE)} -> 34634 | L8: 28Years | M8: 51194.56 | N8: tier - 1 | O8: tier - 3 | P8: R1011 | Q8: =VLOOKUP(A8,'Customer Names'!$A$1:E2342,5,FALSE) -> Scott
A9: Id8 | B9: {=VLOOKUP(A9,'Medical Examinations'!A8:J2343,{2,3,4,5,6,7,8,9},FALSE)} -> 36.96 | C9: Obesity | D9: 7.93 | E9: Diabetes | F9: No | G9: No | H9: No | I9: 3 | J9: Yes | K9: {=VLOOKUP(A9,'Hospitalisation Details'!$A$1:K2351,{5,6,8,9,10,11},FALSE)} -> 21363 | L9: 64Years | M9: 49577.66 | N9: tier - 2 | O9: tier - 2 | P9: R1013 | Q9: =VLOOKUP(A9,'Customer Names'!$A$1:E2343,5,FALSE) -> Stephen
A10: Id9 | B10: {=VLOOKUP(A10,'Medical Examinations'!A9:J2344,{2,3,4,5,6,7,8,9},FALSE)} -> 41.14 | C10: Obesity | D10: 9.58 | E10: Diabetes | F10: Yes | G10: No | H10: Yes | I10: 1 | J10: Yes | K10: {=VLOOKUP(A10,'Hospitalisation Details'!$A$1:K2352,{5,6,8,9,10,11},FALSE)} -> 23258 | L10: 59Years | M10: 48970.25 | N10: tier - 1 | O10: tier - 2 | P10: R1013 | Q10: =VLOOKUP(A10,'Customer Names'!$A$1:E2344,5,FALSE) -> Patrick R
A11: Id10 | B11: {=VLOOKUP(A11,'Medical Examinations'!A10:J2345,{2,3,4,5,6,7,8,9},FALSE)} -> 38.06 | C11: Obesity | D11: 10.79 | E11: Diabetes | F11: No | G11: No | H11: No | I11: 0 | J11: Yes | K11: {=VLOOKUP(A11,'Hospitalisation Details'!$A$1:K2353,{5,6,8,9,10,11},FALSE)} -> 28853 | L11: 44Years | M11: 48885.14 | N11: tier - 1 | O11: tier - 2 | P11: R1013 | Q11: =VLOOKUP(A11,'Customer Names'!$A$1:E2345,5,FALSE) -> Brooke N
A12: Id11 | B12: {=VLOOKUP(A12,'Medical Examinations'!A11:J2346,{2,3,4,5,6,7,8,9},FALSE)} -> 37.7 | C12: Obesity | D12: 5.96 | E12: Prediabetes | F12: Yes | G12: No | H12: No | I12: 2 | J12: Yes | K12: {=VLOOKUP(A12,'Hospitalisation Details'!$A$1:K2354,{5,6,8,9,10,11},FALSE)} -> 21753 | L12: 63Years | M12: 48824.45 | N12: tier - 2 | O12: tier - 1 | P12: R1011 | Q12: =VLOOKUP(A12,'Customer Names'!$A$1:E2346,5,FALSE) -> Paola Andrea
A13: Id12 | B13: {=VLOOKUP(A13,'Medical Examinations'!A12:J2347,{2,3,4,5,6,7,8,9},FALSE)} -> 42.13 | C13: Obesity | D13: 11.9 | E13: Diabetes | F13: No | G13: No | H13: No | I13: 0 | J13: Yes | K13: {=VLOOKUP(A13,'Hospitalisation Details'!$A$1:K2355,{5,6,8,9,10,11},FALSE)} -> 24042 | L13: 57Years | M13: 48675.52 | N13: tier - 1 | O13: tier - 2 | P13: R1013 | Q13: =VLOOKUP(A13,'Customer Names'!$A$1:E2347,5,FALSE) -> David
... A2336: Id2335 | B2336: {=VLOOKUP(A2336,'Medical Examinations'!A2335:J4670,{2,3,4,5,6,7,8,9},FALSE)} -> 17.58 | C2336: Underweight | D2336: 4.51 | E2336: Normal | F2336: No | G2336: No | H2336: No | I2336: 1 | J2336: No | K2336: {=VLOOKUP(A2336,'Hospitalisation Details'!$A$1:K4678,{5,6,8,9,10,11},FALSE)} -> 33794 | L2336: 30Years | M2336: 563.84 | N2336: tier - 2 | O2336: tier - 3 | P2336: R1013 | Q2336: =VLOOKUP(A2336,'Customer Names'!$A$1:E4670,5,FALSE) -> Aaron K
